[2025-01-07T12:53:39] INFO [weather.get_connection:61] Establishing connection to Azure Blob using account name: rupamtesting
[2025-01-07T12:53:39] INFO [weather.get_connection:70] Connection successful to blob
[2025-01-07T12:53:40] INFO [weather.create_container:92] The container with the given name: current-weather already exists. Not creating again.
[2025-01-07T12:53:40] INFO [weather.get_data:42] Fetching weather data from the url : https://openweathermap.org/api
[2025-01-07T12:53:41] INFO [weather.get_data:46] Response status: 200
[2025-01-07T12:53:41] INFO [weather.get_data:47] Data fetched successfully...
[2025-01-07T12:53:41] ERROR [weather.get_data:56] Exception happened : ('Expecting value: line 1 column 1 (char 0)',)
Traceback (most recent call last):
  File "C:\Users\RUPAM\AppData\Local\Programs\Python\Python312\Lib\site-packages\requests\models.py", line 974, in json
    return complexjson.loads(self.text, **kwargs)
           ^^^^^^^^^^^^^^^^^^^^^^^^^^^^^^^^^^^^^^
  File "C:\Users\RUPAM\AppData\Local\Programs\Python\Python312\Lib\site-packages\simplejson\__init__.py", line 514, in loads
    return _default_decoder.decode(s)
           ^^^^^^^^^^^^^^^^^^^^^^^^^^
  File "C:\Users\RUPAM\AppData\Local\Programs\Python\Python312\Lib\site-packages\simplejson\decoder.py", line 386, in decode
    obj, end = self.raw_decode(s)
               ^^^^^^^^^^^^^^^^^^
  File "C:\Users\RUPAM\AppData\Local\Programs\Python\Python312\Lib\site-packages\simplejson\decoder.py", line 416, in raw_decode
    return self.scan_once(s, idx=_w(s, idx).end())
           ^^^^^^^^^^^^^^^^^^^^^^^^^^^^^^^^^^^^^^^
simplejson.errors.JSONDecodeError: Expecting value: line 1 column 1 (char 0)

During handling of the above exception, another exception occurred:

Traceback (most recent call last):
  File "C:\Users\RUPAM\Desktop\Python Projects\Python-Project1-ETL-weather-data-into-Azure-blob\helpers\weather_client.py", line 48, in get_data
    json_data = data.json()
                ^^^^^^^^^^^
  File "C:\Users\RUPAM\AppData\Local\Programs\Python\Python312\Lib\site-packages\requests\models.py", line 978, in json
    raise RequestsJSONDecodeError(e.msg, e.doc, e.pos)
requests.exceptions.JSONDecodeError: Expecting value: line 1 column 1 (char 0)
[2025-01-07T12:53:41] INFO [weather.upload_azure:143] Length of records is: 0
[2025-01-07T12:53:41] INFO [weather.upload_azure:192] There are no records for the table - weather
[2025-01-07T12:53:41] INFO [weather.cleanup:142] Removing folder at ./files
